2019-11-13 15:39:50,773 : INFO : Machine : Mission Pinball Framework Core Engine v0.53.0-dev.67
2019-11-13 15:39:50,774 : INFO : Machine : Command line arguments: {'no_load_cache': False, 'create_config_cache': True, 'bcp': False, 'configfile': ['config.yaml'], 'mpfconfigfile': 'c:\\users\\schol\\appdata\\local\\programs\\python\\python36\\lib\\site-packages\\mpf\\mpfconfig.yaml', 'force_assets_load': False, 'jsonlogging': False, 'logfile': 'logs\\2019-11-13-15-39-50-mpf-DESKTOP-FPTMTCL.log', 'pause': False, 'production': False, 'text_ui': True, 'loglevel': 15, 'consoleloglevel': 20, 'force_platform': None, 'syslog_address': None, 'mc_file_name': None, 'no_sound': False}
2019-11-13 15:39:50,774 : INFO : Machine : MPF path: c:\users\schol\appdata\local\programs\python\python36\lib\site-packages\mpf
2019-11-13 15:39:50,774 : INFO : Machine : Machine path: D:\mpf\wows\wows
2019-11-13 15:39:50,774 : INFO : Machine : Platform: win32
2019-11-13 15:39:50,774 : INFO : Machine : Python executable location: c:\users\schol\appdata\local\programs\python\python36\python.exe
2019-11-13 15:39:50,774 : INFO : Machine : Python version: 3.6.4 (64-bit)
2019-11-13 15:39:50,774 : INFO : Machine : Machine config file #1: config.yaml
2019-11-13 15:39:50,775 : INFO : ConfigProcessor : Loading config from cache: C:\Users\schol\AppData\Local\Temp\9eb68d3894805241b8cf789ebd176e3c.mpf_cache
2019-11-13 15:39:50,821 : INFO : Machine : Initialise MPF.
2019-11-13 15:39:51,093 : INFO : EventManager : Event: ======'machine_var_credits_string'====== Args={'value': 'FREE PLAY', 'prev_value': None, 'change': True}
2019-11-13 15:39:51,128 : INFO : EventManager : Event: ======'machine_var_mpf_version'====== Args={'value': 'MPF v0.53.0-dev.67', 'prev_value': None, 'change': True}
2019-11-13 15:39:51,129 : INFO : EventManager : Event: ======'machine_var_mpf_extended_version'====== Args={'value': 'MPF v0.53.0-dev.67, Config version:5, Show version: 5, BCP version:1.1', 'prev_value': None, 'change': True}
2019-11-13 15:39:51,129 : INFO : EventManager : Event: ======'machine_var_python_version'====== Args={'value': '3.6.4', 'prev_value': None, 'change': True}
2019-11-13 15:39:51,129 : INFO : EventManager : Event: ======'machine_var_platform'====== Args={'value': 'Windows-10-10.0.18362-SP0', 'prev_value': None, 'change': True}
2019-11-13 15:39:51,129 : INFO : EventManager : Event: ======'machine_var_platform_system'====== Args={'value': 'Windows', 'prev_value': None, 'change': True}
2019-11-13 15:39:51,129 : INFO : EventManager : Event: ======'machine_var_platform_release'====== Args={'value': '10', 'prev_value': None, 'change': True}
2019-11-13 15:39:51,129 : INFO : EventManager : Event: ======'machine_var_platform_version'====== Args={'value': '10.0.18362', 'prev_value': None, 'change': True}
2019-11-13 15:39:51,129 : INFO : EventManager : Event: ======'machine_var_platform_machine'====== Args={'value': 'AMD64', 'prev_value': None, 'change': True}
2019-11-13 15:39:51,129 : INFO : EventManager : Event: ======'init_phase_1'====== Args={}
2019-11-13 15:39:51,159 : INFO : ConfigProcessor : Loading config from cache: C:\Users\schol\AppData\Local\Temp\5c4497fcd69d1d656c4b69a28e44c490.mpf_cache
2019-11-13 15:39:51,164 : INFO : ConfigProcessor : Loading config from cache: C:\Users\schol\AppData\Local\Temp\d5fd805c5432c1441bf01a6268536a3d.mpf_cache
2019-11-13 15:39:51,168 : ERROR : asyncio : Exception in callback EventManager._async_handler_done(<QueuedEvent>)(<Task finishe...ictionary.",)>) at c:\users\schol\appdata\local\programs\python\python36\lib\site-packages\mpf\core\events.py:90
handle: <Handle EventManager._async_handler_done(<QueuedEvent>)(<Task finishe...ictionary.",)>) at c:\users\schol\appdata\local\programs\python\python36\lib\site-packages\mpf\core\events.py:90>
Traceback (most recent call last):
  File "c:\users\schol\appdata\local\programs\python\python36\lib\asyncio\events.py", line 145, in _run
    self._callback(*self._args)
  File "c:\users\schol\appdata\local\programs\python\python36\lib\site-packages\mpf\core\events.py", line 93, in _async_handler_done
    future.result()
  File "c:\users\schol\appdata\local\programs\python\python36\lib\site-packages\mpf\core\device_manager.py", line 102, in _load_device_modules
    self.create_devices(collection_name, config)
  File "c:\users\schol\appdata\local\programs\python\python36\lib\site-packages\mpf\core\device_manager.py", line 150, in create_devices
    device_name), 3, context=collection_name + "." + device_name)
  File "c:\users\schol\appdata\local\programs\python\python36\lib\site-packages\mpf\core\logging.py", line 165, in raise_config_error
    raise ConfigFileError(msg, error_no, self.log.name, context, self._url_base)
mpf.exceptions.config_file_error.ConfigFileError: Config File Error in DeviceManager: Device 'allow_enable' does not have a valid config. Expected a dictionary. Context: coils.allow_enable Error Code: CFE-DeviceManager-3 (https://docs.missionpinball.org/en/dev/logs/CFE-DeviceManager-3.html)
2019-11-13 15:39:51,170 : INFO : Machine : Starting the main run loop.
2019-11-13 15:39:51,174 : INFO : Machine : Shutting down...
2019-11-13 15:39:51,174 : INFO : EventManager : Event: ======'shutdown'====== Args={}
2019-11-13 15:39:51,174 : ERROR : Machine : Runtime Exception
Traceback (most recent call last):
  File "c:\users\schol\appdata\local\programs\python\python36\lib\site-packages\mpf\core\machine.py", line 765, in _run_loop
    raise self._exception['exception']
  File "c:\users\schol\appdata\local\programs\python\python36\lib\asyncio\events.py", line 145, in _run
    self._callback(*self._args)
  File "c:\users\schol\appdata\local\programs\python\python36\lib\site-packages\mpf\core\events.py", line 93, in _async_handler_done
    future.result()
  File "c:\users\schol\appdata\local\programs\python\python36\lib\site-packages\mpf\core\device_manager.py", line 102, in _load_device_modules
    self.create_devices(collection_name, config)
  File "c:\users\schol\appdata\local\programs\python\python36\lib\site-packages\mpf\core\device_manager.py", line 150, in create_devices
    device_name), 3, context=collection_name + "." + device_name)
  File "c:\users\schol\appdata\local\programs\python\python36\lib\site-packages\mpf\core\logging.py", line 165, in raise_config_error
    raise ConfigFileError(msg, error_no, self.log.name, context, self._url_base)
mpf.exceptions.config_file_error.ConfigFileError: Config File Error in DeviceManager: Device 'allow_enable' does not have a valid config. Expected a dictionary. Context: coils.allow_enable Error Code: CFE-DeviceManager-3 (https://docs.missionpinball.org/en/dev/logs/CFE-DeviceManager-3.html)
2019-11-13 15:39:51,175 : INFO : root : MPF run loop ended.
