2020-02-05 16:34:27,888 : INFO : Machine : Mission Pinball Framework Core Engine v0.53.0-dev.68
2020-02-05 16:34:27,888 : INFO : Machine : Command line arguments: {'no_load_cache': False, 'create_config_cache': True, 'bcp': True, 'configfile': ['config.yaml'], 'mpfconfigfile': 'c:\\users\\schol\\appdata\\local\\programs\\python\\python36\\lib\\site-packages\\mpf\\mpfconfig.yaml', 'force_assets_load': False, 'jsonlogging': False, 'logfile': 'logs\\2020-02-05-16-34-27-mpf-DESKTOP-FPTMTCL.log', 'pause': False, 'production': False, 'text_ui': True, 'loglevel': 15, 'consoleloglevel': 20, 'force_platform': 'smart_virtual', 'syslog_address': None, 'mc_file_name': None, 'no_sound': False}
2020-02-05 16:34:27,889 : INFO : Machine : MPF path: c:\users\schol\appdata\local\programs\python\python36\lib\site-packages\mpf
2020-02-05 16:34:27,889 : INFO : Machine : Machine path: E:\mpf\wows\wows
2020-02-05 16:34:27,889 : INFO : Machine : Platform: win32
2020-02-05 16:34:27,889 : INFO : Machine : Python executable location: c:\users\schol\appdata\local\programs\python\python36\python.exe
2020-02-05 16:34:27,889 : INFO : Machine : Python version: 3.6.4 (64-bit)
2020-02-05 16:34:27,889 : INFO : Machine : Machine config file #1: config.yaml
2020-02-05 16:34:27,890 : INFO : ConfigProcessor : Loading config from cache: C:\Users\schol\AppData\Local\Temp\a7e9e9e882fa7eca7cb0ba00eaf15121.mpf_cache
2020-02-05 16:34:27,892 : INFO : Machine : Initialise MPF.
2020-02-05 16:34:28,117 : INFO : EventManager : Event: ======'machine_var_credits_string'====== Args={'value': 'FREE PLAY', 'prev_value': None, 'change': True}
2020-02-05 16:34:28,153 : INFO : EventManager : Event: ======'machine_var_player1_score'====== Args={'value': 0, 'prev_value': None, 'change': True}
2020-02-05 16:34:28,153 : INFO : EventManager : Event: ======'machine_var_mpf_version'====== Args={'value': 'MPF v0.53.0-dev.68', 'prev_value': None, 'change': True}
2020-02-05 16:34:28,153 : INFO : EventManager : Event: ======'machine_var_mpf_extended_version'====== Args={'value': 'MPF v0.53.0-dev.68, Config version:5, Show version: 5, BCP version:1.1', 'prev_value': None, 'change': True}
2020-02-05 16:34:28,153 : INFO : EventManager : Event: ======'machine_var_python_version'====== Args={'value': '3.6.4', 'prev_value': None, 'change': True}
2020-02-05 16:34:28,153 : INFO : EventManager : Event: ======'machine_var_platform'====== Args={'value': 'Windows-10-10.0.18362-SP0', 'prev_value': None, 'change': True}
2020-02-05 16:34:28,153 : INFO : EventManager : Event: ======'machine_var_platform_system'====== Args={'value': 'Windows', 'prev_value': None, 'change': True}
2020-02-05 16:34:28,153 : INFO : EventManager : Event: ======'machine_var_platform_release'====== Args={'value': '10', 'prev_value': None, 'change': True}
2020-02-05 16:34:28,154 : INFO : EventManager : Event: ======'machine_var_platform_version'====== Args={'value': '10.0.18362', 'prev_value': None, 'change': True}
2020-02-05 16:34:28,154 : INFO : EventManager : Event: ======'machine_var_platform_machine'====== Args={'value': 'AMD64', 'prev_value': None, 'change': True}
2020-02-05 16:34:28,154 : INFO : EventManager : Event: ======'init_phase_1'====== Args={}
2020-02-05 16:34:28,185 : INFO : ConfigProcessor : Loading config from cache: C:\Users\schol\AppData\Local\Temp\1e6cc6775e87a3e14ded8d45fd065b10.mpf_cache
2020-02-05 16:34:28,188 : INFO : ConfigProcessor : Loading config from cache: C:\Users\schol\AppData\Local\Temp\a6527a592b6034dbfea56fdf726c3822.mpf_cache
2020-02-05 16:34:28,190 : WARNING : ConfigProcessor : Config file in cache changed: E:\mpf\wows\wows\modes\hc_multiball\config\hc_multiball.yaml
2020-02-05 16:34:28,190 : INFO : ConfigProcessor : Loading config from file E:\mpf\wows\wows\modes\hc_multiball\config\hc_multiball.yaml.
2020-02-05 16:34:28,202 : INFO : ConfigProcessor : Loading config: E:\mpf\wows\wows\modes\hc_multiball\config\hc_multiball.yaml
2020-02-05 16:34:28,202 : INFO : ConfigProcessor : Config file cache created: C:\Users\schol\AppData\Local\Temp\97f63c0afcbce8d9df7044fccf1035a4.mpf_cache
2020-02-05 16:34:28,205 : INFO : ConfigProcessor : Loading config from cache: C:\Users\schol\AppData\Local\Temp\f9a57b3955e1480227d6e8589f6567c4.mpf_cache
2020-02-05 16:34:28,207 : INFO : ConfigProcessor : Loading config from cache: C:\Users\schol\AppData\Local\Temp\5c4497fcd69d1d656c4b69a28e44c490.mpf_cache
2020-02-05 16:34:28,212 : INFO : ConfigProcessor : Loading config from cache: C:\Users\schol\AppData\Local\Temp\d5fd805c5432c1441bf01a6268536a3d.mpf_cache
2020-02-05 16:34:28,216 : INFO : ConfigProcessor : Loading config from cache: C:\Users\schol\AppData\Local\Temp\4aeaa69609f53d9b71d1dbbedd434b0b.mpf_cache
2020-02-05 16:34:28,218 : INFO : ConfigProcessor : Loading config from cache: C:\Users\schol\AppData\Local\Temp\1068177614fe5a40fc2c1e1b0504468c.mpf_cache
2020-02-05 16:34:28,220 : INFO : ConfigProcessor : Loading config from cache: C:\Users\schol\AppData\Local\Temp\6e6d4708a613edd7635d35a6961997f3.mpf_cache
2020-02-05 16:34:28,239 : ERROR : asyncio : Exception in callback EventManager._async_handler_done(<QueuedEvent>)(<Task finishe...ot defined',)>) at c:\users\schol\appdata\local\programs\python\python36\lib\site-packages\mpf\core\events.py:90
handle: <Handle EventManager._async_handler_done(<QueuedEvent>)(<Task finishe...ot defined',)>) at c:\users\schol\appdata\local\programs\python\python36\lib\site-packages\mpf\core\events.py:90>
Traceback (most recent call last):
  File "c:\users\schol\appdata\local\programs\python\python36\lib\asyncio\events.py", line 145, in _run
    self._callback(*self._args)
  File "c:\users\schol\appdata\local\programs\python\python36\lib\site-packages\mpf\core\events.py", line 93, in _async_handler_done
    future.result()
  File "c:\users\schol\appdata\local\programs\python\python36\lib\site-packages\mpf\core\device_manager.py", line 114, in _load_device_modules
    await self.machine.mode_controller.load_mode_devices()
  File "c:\users\schol\appdata\local\programs\python\python36\lib\site-packages\mpf\core\mode_controller.py", line 90, in load_mode_devices
    await mode.load_mode_devices()
  File "c:\users\schol\appdata\local\programs\python\python36\lib\site-packages\mpf\core\mode.py", line 437, in load_mode_devices
    settings = device.validate_and_parse_config(settings, True, "mode:" + self.name)
  File "c:\users\schol\appdata\local\programs\python\python36\lib\site-packages\mpf\core\device.py", line 103, in validate_and_parse_config
    self.config_section, config, self.name, "device", prefix=debug_prefix)
  File "c:\users\schol\appdata\local\programs\python\python36\lib\site-packages\mpf\core\config_validator.py", line 281, in validate_config
    validation_failure_info=(validation_failure_info, k))
  File "c:\users\schol\appdata\local\programs\python\python36\lib\site-packages\mpf\core\config_validator.py", line 328, in validate_config_item
    new_list.append(self.validate_item(i, validation, validation_failure_info))
  File "c:\users\schol\appdata\local\programs\python\python36\lib\site-packages\mpf\core\config_validator.py", line 757, in validate_item
    return self.validator_list[validator](item, validation_failure_info=validation_failure_info, param=param)
  File "c:\users\schol\appdata\local\programs\python\python36\lib\site-packages\mpf\core\config_validator.py", line 477, in _validate_type_machine
    6)
  File "c:\users\schol\appdata\local\programs\python\python36\lib\site-packages\mpf\core\config_validator.py", line 776, in validation_error
    item, msg), 5 if code is None else code, self.log.name)
mpf.exceptions.config_file_error.ConfigFileError: Config File Error in ConfigValidator: Config validation error: Entry mode:hc_multiball:multiballs:high_caliber_multiball:ball_locks = "hc_lock" is not valid. Device hc_lock of type ball_devices not defined Error Code: CFE-ConfigValidator-6 (https://docs.missionpinball.org/en/dev/logs/CFE-ConfigValidator-6.html)
2020-02-05 16:34:28,241 : INFO : Machine : Starting the main run loop.
2020-02-05 16:34:28,244 : INFO : Machine : Shutting down...
2020-02-05 16:34:28,244 : INFO : EventManager : Event: ======'shutdown'====== Args={}
2020-02-05 16:34:28,245 : ERROR : Machine : Runtime Exception
Traceback (most recent call last):
  File "c:\users\schol\appdata\local\programs\python\python36\lib\site-packages\mpf\core\machine.py", line 765, in _run_loop
    raise self._exception['exception']
  File "c:\users\schol\appdata\local\programs\python\python36\lib\asyncio\events.py", line 145, in _run
    self._callback(*self._args)
  File "c:\users\schol\appdata\local\programs\python\python36\lib\site-packages\mpf\core\events.py", line 93, in _async_handler_done
    future.result()
  File "c:\users\schol\appdata\local\programs\python\python36\lib\site-packages\mpf\core\device_manager.py", line 114, in _load_device_modules
    await self.machine.mode_controller.load_mode_devices()
  File "c:\users\schol\appdata\local\programs\python\python36\lib\site-packages\mpf\core\mode_controller.py", line 90, in load_mode_devices
    await mode.load_mode_devices()
  File "c:\users\schol\appdata\local\programs\python\python36\lib\site-packages\mpf\core\mode.py", line 437, in load_mode_devices
    settings = device.validate_and_parse_config(settings, True, "mode:" + self.name)
  File "c:\users\schol\appdata\local\programs\python\python36\lib\site-packages\mpf\core\device.py", line 103, in validate_and_parse_config
    self.config_section, config, self.name, "device", prefix=debug_prefix)
  File "c:\users\schol\appdata\local\programs\python\python36\lib\site-packages\mpf\core\config_validator.py", line 281, in validate_config
    validation_failure_info=(validation_failure_info, k))
  File "c:\users\schol\appdata\local\programs\python\python36\lib\site-packages\mpf\core\config_validator.py", line 328, in validate_config_item
    new_list.append(self.validate_item(i, validation, validation_failure_info))
  File "c:\users\schol\appdata\local\programs\python\python36\lib\site-packages\mpf\core\config_validator.py", line 757, in validate_item
    return self.validator_list[validator](item, validation_failure_info=validation_failure_info, param=param)
  File "c:\users\schol\appdata\local\programs\python\python36\lib\site-packages\mpf\core\config_validator.py", line 477, in _validate_type_machine
    6)
  File "c:\users\schol\appdata\local\programs\python\python36\lib\site-packages\mpf\core\config_validator.py", line 776, in validation_error
    item, msg), 5 if code is None else code, self.log.name)
mpf.exceptions.config_file_error.ConfigFileError: Config File Error in ConfigValidator: Config validation error: Entry mode:hc_multiball:multiballs:high_caliber_multiball:ball_locks = "hc_lock" is not valid. Device hc_lock of type ball_devices not defined Error Code: CFE-ConfigValidator-6 (https://docs.missionpinball.org/en/dev/logs/CFE-ConfigValidator-6.html)
2020-02-05 16:34:28,246 : INFO : root : MPF run loop ended.
