2020-02-04 22:15:54,360 : INFO : Machine : Mission Pinball Framework Core Engine v0.53.0-dev.68
2020-02-04 22:15:54,361 : INFO : Machine : Command line arguments: {'no_load_cache': False, 'create_config_cache': True, 'bcp': True, 'configfile': ['config.yaml'], 'mpfconfigfile': 'c:\\users\\schol\\appdata\\local\\programs\\python\\python36\\lib\\site-packages\\mpf\\mpfconfig.yaml', 'force_assets_load': False, 'jsonlogging': False, 'logfile': 'logs\\2020-02-04-22-15-54-mpf-DESKTOP-FPTMTCL.log', 'pause': False, 'production': False, 'text_ui': True, 'loglevel': 15, 'consoleloglevel': 20, 'force_platform': 'smart_virtual', 'syslog_address': None, 'mc_file_name': None, 'no_sound': False}
2020-02-04 22:15:54,361 : INFO : Machine : MPF path: c:\users\schol\appdata\local\programs\python\python36\lib\site-packages\mpf
2020-02-04 22:15:54,361 : INFO : Machine : Machine path: E:\mpf\wows\wows
2020-02-04 22:15:54,361 : INFO : Machine : Platform: win32
2020-02-04 22:15:54,361 : INFO : Machine : Python executable location: c:\users\schol\appdata\local\programs\python\python36\python.exe
2020-02-04 22:15:54,361 : INFO : Machine : Python version: 3.6.4 (64-bit)
2020-02-04 22:15:54,361 : INFO : Machine : Machine config file #1: config.yaml
2020-02-04 22:15:54,362 : INFO : ConfigProcessor : Loading config from cache: C:\Users\schol\AppData\Local\Temp\a7e9e9e882fa7eca7cb0ba00eaf15121.mpf_cache
2020-02-04 22:15:54,364 : INFO : Machine : Initialise MPF.
2020-02-04 22:15:54,593 : INFO : EventManager : Event: ======'machine_var_credits_string'====== Args={'value': 'FREE PLAY', 'prev_value': None, 'change': True}
2020-02-04 22:15:54,628 : INFO : EventManager : Event: ======'machine_var_player1_score'====== Args={'value': 0, 'prev_value': None, 'change': True}
2020-02-04 22:15:54,628 : INFO : EventManager : Event: ======'machine_var_mpf_version'====== Args={'value': 'MPF v0.53.0-dev.68', 'prev_value': None, 'change': True}
2020-02-04 22:15:54,628 : INFO : EventManager : Event: ======'machine_var_mpf_extended_version'====== Args={'value': 'MPF v0.53.0-dev.68, Config version:5, Show version: 5, BCP version:1.1', 'prev_value': None, 'change': True}
2020-02-04 22:15:54,628 : INFO : EventManager : Event: ======'machine_var_python_version'====== Args={'value': '3.6.4', 'prev_value': None, 'change': True}
2020-02-04 22:15:54,629 : INFO : EventManager : Event: ======'machine_var_platform'====== Args={'value': 'Windows-10-10.0.18362-SP0', 'prev_value': None, 'change': True}
2020-02-04 22:15:54,629 : INFO : EventManager : Event: ======'machine_var_platform_system'====== Args={'value': 'Windows', 'prev_value': None, 'change': True}
2020-02-04 22:15:54,629 : INFO : EventManager : Event: ======'machine_var_platform_release'====== Args={'value': '10', 'prev_value': None, 'change': True}
2020-02-04 22:15:54,629 : INFO : EventManager : Event: ======'machine_var_platform_version'====== Args={'value': '10.0.18362', 'prev_value': None, 'change': True}
2020-02-04 22:15:54,629 : INFO : EventManager : Event: ======'machine_var_platform_machine'====== Args={'value': 'AMD64', 'prev_value': None, 'change': True}
2020-02-04 22:15:54,629 : INFO : EventManager : Event: ======'init_phase_1'====== Args={}
2020-02-04 22:15:54,661 : WARNING : ConfigProcessor : Config file in cache changed: E:\mpf\wows\wows\modes\hc_lock_lit\config\hc_lock_lit.yaml
2020-02-04 22:15:54,661 : INFO : ConfigProcessor : Loading config from file E:\mpf\wows\wows\modes\hc_lock_lit\config\hc_lock_lit.yaml.
2020-02-04 22:15:54,673 : INFO : ConfigProcessor : Loading config: E:\mpf\wows\wows\modes\hc_lock_lit\config\hc_lock_lit.yaml
2020-02-04 22:15:54,673 : INFO : ConfigProcessor : Config file cache created: C:\Users\schol\AppData\Local\Temp\2f7452aae1b2779bb4a1388fc419c0c8.mpf_cache
2020-02-04 22:15:54,676 : INFO : ConfigProcessor : Loading config from cache: C:\Users\schol\AppData\Local\Temp\6e6d4708a613edd7635d35a6961997f3.mpf_cache
2020-02-04 22:15:54,678 : INFO : ConfigProcessor : Loading config from cache: C:\Users\schol\AppData\Local\Temp\1068177614fe5a40fc2c1e1b0504468c.mpf_cache
2020-02-04 22:15:54,680 : INFO : ConfigProcessor : Loading config from cache: C:\Users\schol\AppData\Local\Temp\4aeaa69609f53d9b71d1dbbedd434b0b.mpf_cache
2020-02-04 22:15:54,682 : INFO : ConfigProcessor : Loading config from cache: C:\Users\schol\AppData\Local\Temp\5c4497fcd69d1d656c4b69a28e44c490.mpf_cache
2020-02-04 22:15:54,688 : INFO : ConfigProcessor : Loading config from cache: C:\Users\schol\AppData\Local\Temp\a6527a592b6034dbfea56fdf726c3822.mpf_cache
2020-02-04 22:15:54,690 : INFO : ConfigProcessor : Loading config from cache: C:\Users\schol\AppData\Local\Temp\1e6cc6775e87a3e14ded8d45fd065b10.mpf_cache
2020-02-04 22:15:54,692 : INFO : ConfigProcessor : Loading config from cache: C:\Users\schol\AppData\Local\Temp\d5fd805c5432c1441bf01a6268536a3d.mpf_cache
2020-02-04 22:15:54,696 : INFO : ConfigProcessor : Loading config from cache: C:\Users\schol\AppData\Local\Temp\f9a57b3955e1480227d6e8589f6567c4.mpf_cache
2020-02-04 22:15:54,723 : INFO : EventManager : Event: ======'init_phase_2'====== Args={}
2020-02-04 22:15:54,723 : INFO : SwitchController : Found active switch: ('2', <Platform.SmartVirtual>)
2020-02-04 22:15:54,724 : INFO : SwitchController : Found active switch: ('3', <Platform.SmartVirtual>)
2020-02-04 22:15:54,724 : INFO : SwitchController : Found active switch: ('4', <Platform.SmartVirtual>)
2020-02-04 22:15:54,724 : INFO : SwitchController : Found active switch: ('5', <Platform.SmartVirtual>)
2020-02-04 22:15:54,724 : INFO : SwitchController : Found active switch: ('6', <Platform.SmartVirtual>)
2020-02-04 22:15:54,724 : INFO : SwitchController : Found active switch: ('7', <Platform.SmartVirtual>)
2020-02-04 22:15:54,727 : ERROR : asyncio : Exception in callback EventManager._done(<Task finishe...ow': None}",)>)
handle: <Handle EventManager._done(<Task finishe...ow': None}",)>)>
Traceback (most recent call last):
  File "c:\users\schol\appdata\local\programs\python\python36\lib\site-packages\mpf\config_players\device_config_player.py", line 49, in validate_config_entry
    self._validate_config_item(device, device_settings))
  File "c:\users\schol\appdata\local\programs\python\python36\lib\site-packages\mpf\config_players\device_config_player.py", line 75, in _validate_config_item
    device_settings = self._parse_config(device_settings, device)
  File "c:\users\schol\appdata\local\programs\python\python36\lib\site-packages\mpf\core\config_player.py", line 127, in _parse_config
    return self.get_full_config(config)
  File "c:\users\schol\appdata\local\programs\python\python36\lib\site-packages\mpf\core\config_player.py", line 199, in get_full_config
    self.config_file_section, value, base_spec='config_player_common')
  File "c:\users\schol\appdata\local\programs\python\python36\lib\site-packages\mpf\core\config_validator.py", line 281, in validate_config
    validation_failure_info=(validation_failure_info, k))
  File "c:\users\schol\appdata\local\programs\python\python36\lib\site-packages\mpf\core\config_validator.py", line 320, in validate_config_item
    validation_failure_info)
  File "c:\users\schol\appdata\local\programs\python\python36\lib\site-packages\mpf\core\config_validator.py", line 757, in validate_item
    return self.validator_list[validator](item, validation_failure_info=validation_failure_info, param=param)
  File "c:\users\schol\appdata\local\programs\python\python36\lib\site-packages\mpf\core\config_validator.py", line 459, in _validate_type_enum
    item, str(param)))
  File "c:\users\schol\appdata\local\programs\python\python36\lib\site-packages\mpf\core\config_validator.py", line 776, in validation_error
    item, msg), 5 if code is None else code, self.log.name)
mpf.exceptions.config_file_error.ConfigFileError: Config File Error in ConfigValidator: Config validation error: Entry show_player:show_player:action = "lock_lit_start_1_light_show" is not valid. Entry "lock_lit_start_1_light_show" is not valid for enum. Valid values are: play,stop,pause,resume,advance,step_back,update Error Code: CFE-ConfigValidator-5 (https://docs.missionpinball.org/en/dev/logs/CFE-ConfigValidator-5.html)

The above exception was the direct cause of the following exception:

Traceback (most recent call last):
  File "c:\users\schol\appdata\local\programs\python\python36\lib\asyncio\events.py", line 145, in _run
    self._callback(*self._args)
  File "c:\users\schol\appdata\local\programs\python\python36\lib\site-packages\mpf\core\events.py", line 695, in _done
    future.result()
  File "c:\users\schol\appdata\local\programs\python\python36\lib\site-packages\mpf\core\events.py", line 612, in _run_handlers_sequential
    handler.callback(queue=queue, **merged_kwargs)
  File "c:\users\schol\appdata\local\programs\python\python36\lib\site-packages\mpf\core\mode_controller.py", line 96, in initialise_modes
    mode.initialise_mode()
  File "c:\users\schol\appdata\local\programs\python\python36\lib\site-packages\mpf\core\mode.py", line 576, in initialise_mode
    **item.kwargs)
  File "c:\users\schol\appdata\local\programs\python\python36\lib\site-packages\mpf\core\config_player.py", line 133, in process_mode_config
    config = self.validate_config(config)
  File "c:\users\schol\appdata\local\programs\python\python36\lib\site-packages\mpf\core\config_player.py", line 105, in validate_config
    validated_config[event] = self.validate_config_entry(settings, event)
  File "c:\users\schol\appdata\local\programs\python\python36\lib\site-packages\mpf\config_players\device_config_player.py", line 52, in validate_config_entry
    name, self.show_section, settings), 1, self.log.name) from e
mpf.exceptions.config_file_error.ConfigFileError: Config File Error in show_player: Failed to load config player lock_lit_start_light:shows {'lock_lit_start_1_light_show': None, 'lock_lit_start_2_light_show': None} Error Code: CFE-show_player-1 (https://docs.missionpinball.org/en/dev/logs/CFE-show_player-1.html)
2020-02-04 22:15:54,753 : INFO : Machine : Starting the main run loop.
2020-02-04 22:15:54,756 : INFO : Machine : Shutting down...
2020-02-04 22:15:54,756 : INFO : EventManager : Event: ======'shutdown'====== Args={}
2020-02-04 22:15:54,757 : ERROR : Machine : Runtime Exception
Traceback (most recent call last):
  File "c:\users\schol\appdata\local\programs\python\python36\lib\site-packages\mpf\config_players\device_config_player.py", line 49, in validate_config_entry
    self._validate_config_item(device, device_settings))
  File "c:\users\schol\appdata\local\programs\python\python36\lib\site-packages\mpf\config_players\device_config_player.py", line 75, in _validate_config_item
    device_settings = self._parse_config(device_settings, device)
  File "c:\users\schol\appdata\local\programs\python\python36\lib\site-packages\mpf\core\config_player.py", line 127, in _parse_config
    return self.get_full_config(config)
  File "c:\users\schol\appdata\local\programs\python\python36\lib\site-packages\mpf\core\config_player.py", line 199, in get_full_config
    self.config_file_section, value, base_spec='config_player_common')
  File "c:\users\schol\appdata\local\programs\python\python36\lib\site-packages\mpf\core\config_validator.py", line 281, in validate_config
    validation_failure_info=(validation_failure_info, k))
  File "c:\users\schol\appdata\local\programs\python\python36\lib\site-packages\mpf\core\config_validator.py", line 320, in validate_config_item
    validation_failure_info)
  File "c:\users\schol\appdata\local\programs\python\python36\lib\site-packages\mpf\core\config_validator.py", line 757, in validate_item
    return self.validator_list[validator](item, validation_failure_info=validation_failure_info, param=param)
  File "c:\users\schol\appdata\local\programs\python\python36\lib\site-packages\mpf\core\config_validator.py", line 459, in _validate_type_enum
    item, str(param)))
  File "c:\users\schol\appdata\local\programs\python\python36\lib\site-packages\mpf\core\config_validator.py", line 776, in validation_error
    item, msg), 5 if code is None else code, self.log.name)
mpf.exceptions.config_file_error.ConfigFileError: Config File Error in ConfigValidator: Config validation error: Entry show_player:show_player:action = "lock_lit_start_1_light_show" is not valid. Entry "lock_lit_start_1_light_show" is not valid for enum. Valid values are: play,stop,pause,resume,advance,step_back,update Error Code: CFE-ConfigValidator-5 (https://docs.missionpinball.org/en/dev/logs/CFE-ConfigValidator-5.html)

The above exception was the direct cause of the following exception:

Traceback (most recent call last):
  File "c:\users\schol\appdata\local\programs\python\python36\lib\site-packages\mpf\core\machine.py", line 765, in _run_loop
    raise self._exception['exception']
  File "c:\users\schol\appdata\local\programs\python\python36\lib\asyncio\events.py", line 145, in _run
    self._callback(*self._args)
  File "c:\users\schol\appdata\local\programs\python\python36\lib\site-packages\mpf\core\events.py", line 695, in _done
    future.result()
  File "c:\users\schol\appdata\local\programs\python\python36\lib\site-packages\mpf\core\events.py", line 612, in _run_handlers_sequential
    handler.callback(queue=queue, **merged_kwargs)
  File "c:\users\schol\appdata\local\programs\python\python36\lib\site-packages\mpf\core\mode_controller.py", line 96, in initialise_modes
    mode.initialise_mode()
  File "c:\users\schol\appdata\local\programs\python\python36\lib\site-packages\mpf\core\mode.py", line 576, in initialise_mode
    **item.kwargs)
  File "c:\users\schol\appdata\local\programs\python\python36\lib\site-packages\mpf\core\config_player.py", line 133, in process_mode_config
    config = self.validate_config(config)
  File "c:\users\schol\appdata\local\programs\python\python36\lib\site-packages\mpf\core\config_player.py", line 105, in validate_config
    validated_config[event] = self.validate_config_entry(settings, event)
  File "c:\users\schol\appdata\local\programs\python\python36\lib\site-packages\mpf\config_players\device_config_player.py", line 52, in validate_config_entry
    name, self.show_section, settings), 1, self.log.name) from e
mpf.exceptions.config_file_error.ConfigFileError: Config File Error in show_player: Failed to load config player lock_lit_start_light:shows {'lock_lit_start_1_light_show': None, 'lock_lit_start_2_light_show': None} Error Code: CFE-show_player-1 (https://docs.missionpinball.org/en/dev/logs/CFE-show_player-1.html)
2020-02-04 22:15:54,758 : INFO : root : MPF run loop ended.
