2020-05-13 17:07:37,606 : kivy : Factory: 184 symbols loaded
2020-05-13 17:07:37,824 : kivy : Image: Providers: img_tex, img_dds, img_sdl2, img_pil, img_gif (img_ffpyplayer ignored)
2020-05-13 17:07:38,012 : kivy : VideoGstplayer: Using Gstreamer 1.16.0.0
2020-05-13 17:07:38,013 : kivy : Video: Provider: gstplayer
2020-05-13 17:07:38,146 : kivy : Loading MPF-MC controller
2020-05-13 17:07:38,146 : mpfmc : Mission Pinball Framework Media Controller v0.53.0
2020-05-13 17:07:38,147 : mpfmc : Mission Pinball Framework Game Engine v0.53.2
2020-05-13 17:07:38,147 : mpfmc : Machine path: E:\MPF\wows\wows
2020-05-13 17:07:38,148 : ConfigProcessor : Config file in cache changed: E:\MPF\wows\wows\config\config
2020-05-13 17:07:38,149 : ConfigProcessor : Loading config from file c:\users\schol\appdata\local\programs\python\python36\lib\site-packages\mpfmc\mcconfig.yaml.
2020-05-13 17:07:38,209 : ConfigProcessor : Loading config: c:\users\schol\appdata\local\programs\python\python36\lib\site-packages\mpfmc\mcconfig.yaml
2020-05-13 17:07:38,218 : ConfigProcessor : Loading config from file E:\MPF\wows\wows\config\config.
2020-05-13 17:07:38,370 : ConfigProcessor : Loading config: E:\MPF\wows\wows\config\config
2020-05-13 17:07:38,373 : kivy : Config File Error in ConfigProcessor: Found a "pin2dmd:" section in config file E:\MPF\wows\wows\config\config, but that section name is unknown. Did you mean "rpi_dmd:" instead?. Context: E:\MPF\wows\wows\config\config Error Code: CFE-ConfigProcessor-3 (https://docs.missionpinball.org/en/0.53/logs/CFE-ConfigProcessor-3.html)
Traceback (most recent call last):
  File "c:\users\schol\appdata\local\programs\python\python36\lib\site-packages\mpf\core\config_processor.py", line 146, in _check_sections
    if config_type not in config_spec[k]['__valid_in__']:
KeyError: 'pin2dmd'

During handling of the above exception, another exception occurred:

Traceback (most recent call last):
  File "c:\users\schol\appdata\local\programs\python\python36\lib\site-packages\mpfmc\commands\mc.py", line 213, in __init__
    thread_stopper=thread_stopper).run()
  File "c:\users\schol\appdata\local\programs\python\python36\lib\site-packages\mpfmc\core\mc.py", line 97, in __init__
    self.machine_config = self._load_config()
  File "c:\users\schol\appdata\local\programs\python\python36\lib\site-packages\mpfmc\core\mc.py", line 223, in _load_config
    mpf_config = self.mpf_config_processor.load_config_files_with_cache(files, "machine", True)
  File "c:\users\schol\appdata\local\programs\python\python36\lib\site-packages\mpf\core\config_processor.py", line 113, in load_config_files_with_cache
    ignore_unknown_sections)
  File "c:\users\schol\appdata\local\programs\python\python36\lib\site-packages\mpf\core\config_processor.py", line 178, in _load_config_file_and_return_loaded_files
    self._check_sections(config, config_type, filename, ignore_unknown_sections)
  File "c:\users\schol\appdata\local\programs\python\python36\lib\site-packages\mpf\core\config_processor.py", line 159, in _check_sections
    filename)
mpf.exceptions.config_file_error.ConfigFileError: Config File Error in ConfigProcessor: Found a "pin2dmd:" section in config file E:\MPF\wows\wows\config\config, but that section name is unknown. Did you mean "rpi_dmd:" instead?. Context: E:\MPF\wows\wows\config\config Error Code: CFE-ConfigProcessor-3 (https://docs.missionpinball.org/en/0.53/logs/CFE-ConfigProcessor-3.html)
2020-05-13 17:07:38,414 : kivy : Stopping child threads... (0 remaining)
2020-05-13 17:07:38,414 : kivy : All child threads stopped.
