2020-02-09 15:54:30,523 : INFO : Machine : Mission Pinball Framework Core Engine v0.53.0-dev.68
2020-02-09 15:54:30,523 : INFO : Machine : Command line arguments: {'no_load_cache': False, 'create_config_cache': True, 'bcp': True, 'configfile': ['config.yaml'], 'mpfconfigfile': 'c:\\users\\schol\\appdata\\local\\programs\\python\\python36\\lib\\site-packages\\mpf\\mpfconfig.yaml', 'force_assets_load': False, 'jsonlogging': False, 'logfile': 'logs\\2020-02-09-15-54-30-mpf-DESKTOP-FPTMTCL.log', 'pause': False, 'production': False, 'text_ui': True, 'loglevel': 15, 'consoleloglevel': 20, 'force_platform': 'smart_virtual', 'syslog_address': None, 'mc_file_name': None, 'no_sound': False}
2020-02-09 15:54:30,523 : INFO : Machine : MPF path: c:\users\schol\appdata\local\programs\python\python36\lib\site-packages\mpf
2020-02-09 15:54:30,523 : INFO : Machine : Machine path: E:\mpf\wows\wows
2020-02-09 15:54:30,523 : INFO : Machine : Platform: win32
2020-02-09 15:54:30,523 : INFO : Machine : Python executable location: c:\users\schol\appdata\local\programs\python\python36\python.exe
2020-02-09 15:54:30,523 : INFO : Machine : Python version: 3.6.4 (64-bit)
2020-02-09 15:54:30,523 : INFO : Machine : Machine config file #1: config.yaml
2020-02-09 15:54:30,525 : WARNING : ConfigProcessor : Config file in cache changed: E:\mpf\wows\wows\config\config.yaml
2020-02-09 15:54:30,525 : INFO : ConfigProcessor : Loading config from file c:\users\schol\appdata\local\programs\python\python36\lib\site-packages\mpf\mpfconfig.yaml.
2020-02-09 15:54:30,602 : INFO : ConfigProcessor : Loading config: c:\users\schol\appdata\local\programs\python\python36\lib\site-packages\mpf\mpfconfig.yaml
2020-02-09 15:54:30,609 : INFO : ConfigProcessor : Loading config from file E:\mpf\wows\wows\config\config.yaml.
2020-02-09 15:54:30,705 : INFO : ConfigProcessor : Loading config: E:\mpf\wows\wows\config\config.yaml
2020-02-09 15:54:30,707 : INFO : ConfigProcessor : Config file cache created: C:\Users\schol\AppData\Local\Temp\a7e9e9e882fa7eca7cb0ba00eaf15121.mpf_cache
2020-02-09 15:54:30,708 : INFO : Machine : Initialise MPF.
2020-02-09 15:54:30,930 : INFO : EventManager : Event: ======'machine_var_credits_string'====== Args={'value': 'FREE PLAY', 'prev_value': None, 'change': True}
2020-02-09 15:54:30,967 : INFO : EventManager : Event: ======'machine_var_player1_score'====== Args={'value': 0, 'prev_value': None, 'change': True}
2020-02-09 15:54:30,967 : INFO : EventManager : Event: ======'machine_var_mpf_version'====== Args={'value': 'MPF v0.53.0-dev.68', 'prev_value': None, 'change': True}
2020-02-09 15:54:30,967 : INFO : EventManager : Event: ======'machine_var_mpf_extended_version'====== Args={'value': 'MPF v0.53.0-dev.68, Config version:5, Show version: 5, BCP version:1.1', 'prev_value': None, 'change': True}
2020-02-09 15:54:30,967 : INFO : EventManager : Event: ======'machine_var_python_version'====== Args={'value': '3.6.4', 'prev_value': None, 'change': True}
2020-02-09 15:54:30,968 : INFO : EventManager : Event: ======'machine_var_platform'====== Args={'value': 'Windows-10-10.0.18362-SP0', 'prev_value': None, 'change': True}
2020-02-09 15:54:30,968 : INFO : EventManager : Event: ======'machine_var_platform_system'====== Args={'value': 'Windows', 'prev_value': None, 'change': True}
2020-02-09 15:54:30,968 : INFO : EventManager : Event: ======'machine_var_platform_release'====== Args={'value': '10', 'prev_value': None, 'change': True}
2020-02-09 15:54:30,968 : INFO : EventManager : Event: ======'machine_var_platform_version'====== Args={'value': '10.0.18362', 'prev_value': None, 'change': True}
2020-02-09 15:54:30,968 : INFO : EventManager : Event: ======'machine_var_platform_machine'====== Args={'value': 'AMD64', 'prev_value': None, 'change': True}
2020-02-09 15:54:30,968 : INFO : EventManager : Event: ======'init_phase_1'====== Args={}
2020-02-09 15:54:31,002 : WARNING : ConfigProcessor : Cache file not found: C:\Users\schol\AppData\Local\Temp\5dbeda7d2775496a54d206d506904281.mpf_cache
2020-02-09 15:54:31,003 : INFO : ConfigProcessor : Loading config from file E:\mpf\wows\wows\modes\mode_manager\config\mode_manager.yaml.
2020-02-09 15:54:31,013 : INFO : ConfigProcessor : Loading config: E:\mpf\wows\wows\modes\mode_manager\config\mode_manager.yaml
2020-02-09 15:54:31,013 : INFO : ConfigProcessor : Config file cache created: C:\Users\schol\AppData\Local\Temp\5dbeda7d2775496a54d206d506904281.mpf_cache
2020-02-09 15:54:31,015 : INFO : ConfigProcessor : Loading config from cache: C:\Users\schol\AppData\Local\Temp\1e6cc6775e87a3e14ded8d45fd065b10.mpf_cache
2020-02-09 15:54:31,017 : INFO : ConfigProcessor : Loading config from cache: C:\Users\schol\AppData\Local\Temp\a6527a592b6034dbfea56fdf726c3822.mpf_cache
2020-02-09 15:54:31,019 : INFO : ConfigProcessor : Loading config from cache: C:\Users\schol\AppData\Local\Temp\fbcc5772262340622f93ebd98450e45f.mpf_cache
2020-02-09 15:54:31,021 : INFO : ConfigProcessor : Loading config from cache: C:\Users\schol\AppData\Local\Temp\d5fd805c5432c1441bf01a6268536a3d.mpf_cache
2020-02-09 15:54:31,026 : INFO : ConfigProcessor : Loading config from cache: C:\Users\schol\AppData\Local\Temp\5c4497fcd69d1d656c4b69a28e44c490.mpf_cache
2020-02-09 15:54:31,031 : INFO : ConfigProcessor : Loading config from cache: C:\Users\schol\AppData\Local\Temp\2f7452aae1b2779bb4a1388fc419c0c8.mpf_cache
2020-02-09 15:54:31,033 : WARNING : ConfigProcessor : Config file in cache changed: E:\mpf\wows\wows\modes\mode_1\config\mode_1.yaml
2020-02-09 15:54:31,033 : INFO : ConfigProcessor : Loading config from file E:\mpf\wows\wows\modes\mode_1\config\mode_1.yaml.
2020-02-09 15:54:31,039 : INFO : ConfigProcessor : Loading config: E:\mpf\wows\wows\modes\mode_1\config\mode_1.yaml
2020-02-09 15:54:31,040 : INFO : ConfigProcessor : Config file cache created: C:\Users\schol\AppData\Local\Temp\4aeaa69609f53d9b71d1dbbedd434b0b.mpf_cache
2020-02-09 15:54:31,042 : WARNING : ConfigProcessor : Cache file not found: C:\Users\schol\AppData\Local\Temp\a7d542bdfda847f6f43ef69f33227d54.mpf_cache
2020-02-09 15:54:31,042 : INFO : ConfigProcessor : Loading config from file E:\mpf\wows\wows\modes\mode_timer\config\mode_timer.yaml.
2020-02-09 15:54:31,054 : INFO : ConfigProcessor : Loading config: E:\mpf\wows\wows\modes\mode_timer\config\mode_timer.yaml
2020-02-09 15:54:31,055 : INFO : ConfigProcessor : Config file cache created: C:\Users\schol\AppData\Local\Temp\a7d542bdfda847f6f43ef69f33227d54.mpf_cache
2020-02-09 15:54:31,057 : INFO : ConfigProcessor : Loading config from cache: C:\Users\schol\AppData\Local\Temp\97f63c0afcbce8d9df7044fccf1035a4.mpf_cache
2020-02-09 15:54:31,059 : INFO : ConfigProcessor : Loading config from cache: C:\Users\schol\AppData\Local\Temp\f9a57b3955e1480227d6e8589f6567c4.mpf_cache
2020-02-09 15:54:31,061 : INFO : ConfigProcessor : Loading config from cache: C:\Users\schol\AppData\Local\Temp\6e6d4708a613edd7635d35a6961997f3.mpf_cache
2020-02-09 15:54:31,081 : ERROR : ConfigValidator : Your config contains a value for the setting "timer_control_events:(('mode:mode_timer:timers', 'mode_overtime'), 'control_events'):events", but this is not a valid setting name.
2020-02-09 15:54:31,081 : ERROR : asyncio : Exception in callback EventManager._async_handler_done(<QueuedEvent>)(<Task finishe...ting name.',)>) at c:\users\schol\appdata\local\programs\python\python36\lib\site-packages\mpf\core\events.py:90
handle: <Handle EventManager._async_handler_done(<QueuedEvent>)(<Task finishe...ting name.',)>) at c:\users\schol\appdata\local\programs\python\python36\lib\site-packages\mpf\core\events.py:90>
Traceback (most recent call last):
  File "c:\users\schol\appdata\local\programs\python\python36\lib\asyncio\events.py", line 145, in _run
    self._callback(*self._args)
  File "c:\users\schol\appdata\local\programs\python\python36\lib\site-packages\mpf\core\events.py", line 93, in _async_handler_done
    future.result()
  File "c:\users\schol\appdata\local\programs\python\python36\lib\site-packages\mpf\core\device_manager.py", line 114, in _load_device_modules
    await self.machine.mode_controller.load_mode_devices()
  File "c:\users\schol\appdata\local\programs\python\python36\lib\site-packages\mpf\core\mode_controller.py", line 90, in load_mode_devices
    await mode.load_mode_devices()
  File "c:\users\schol\appdata\local\programs\python\python36\lib\site-packages\mpf\core\mode.py", line 437, in load_mode_devices
    settings = device.validate_and_parse_config(settings, True, "mode:" + self.name)
  File "c:\users\schol\appdata\local\programs\python\python36\lib\site-packages\mpf\core\device.py", line 103, in validate_and_parse_config
    self.config_section, config, self.name, "device", prefix=debug_prefix)
  File "c:\users\schol\appdata\local\programs\python\python36\lib\site-packages\mpf\core\config_validator.py", line 281, in validate_config
    validation_failure_info=(validation_failure_info, k))
  File "c:\users\schol\appdata\local\programs\python\python36\lib\site-packages\mpf\core\config_validator.py", line 328, in validate_config_item
    new_list.append(self.validate_item(i, validation, validation_failure_info))
  File "c:\users\schol\appdata\local\programs\python\python36\lib\site-packages\mpf\core\config_validator.py", line 757, in validate_item
    return self.validator_list[validator](item, validation_failure_info=validation_failure_info, param=param)
  File "c:\users\schol\appdata\local\programs\python\python36\lib\site-packages\mpf\core\config_validator.py", line 436, in _validate_type_subconfig
    return self.validate_config(attribute, item, section_name=str(validation_failure_info), base_spec=base_spec)
  File "c:\users\schol\appdata\local\programs\python\python36\lib\site-packages\mpf\core\config_validator.py", line 251, in validate_config
    validation_failure_info)
  File "c:\users\schol\appdata\local\programs\python\python36\lib\site-packages\mpf\core\config_validator.py", line 418, in check_for_invalid_sections
    'setting name.', 2, self.log.name)
mpf.exceptions.config_file_error.ConfigFileError: Config File Error in ConfigValidator: Your config contains a value for the setting "timer_control_events:(('mode:mode_timer:timers', 'mode_overtime'), 'control_events'):events", but this is not a valid setting name. Error Code: CFE-ConfigValidator-2 (https://docs.missionpinball.org/en/dev/logs/CFE-ConfigValidator-2.html)
2020-02-09 15:54:31,126 : INFO : Machine : Starting the main run loop.
2020-02-09 15:54:31,128 : INFO : Machine : Shutting down...
2020-02-09 15:54:31,128 : INFO : EventManager : Event: ======'shutdown'====== Args={}
2020-02-09 15:54:31,129 : ERROR : Machine : Runtime Exception
Traceback (most recent call last):
  File "c:\users\schol\appdata\local\programs\python\python36\lib\site-packages\mpf\core\machine.py", line 765, in _run_loop
    raise self._exception['exception']
  File "c:\users\schol\appdata\local\programs\python\python36\lib\asyncio\events.py", line 145, in _run
    self._callback(*self._args)
  File "c:\users\schol\appdata\local\programs\python\python36\lib\site-packages\mpf\core\events.py", line 93, in _async_handler_done
    future.result()
  File "c:\users\schol\appdata\local\programs\python\python36\lib\site-packages\mpf\core\device_manager.py", line 114, in _load_device_modules
    await self.machine.mode_controller.load_mode_devices()
  File "c:\users\schol\appdata\local\programs\python\python36\lib\site-packages\mpf\core\mode_controller.py", line 90, in load_mode_devices
    await mode.load_mode_devices()
  File "c:\users\schol\appdata\local\programs\python\python36\lib\site-packages\mpf\core\mode.py", line 437, in load_mode_devices
    settings = device.validate_and_parse_config(settings, True, "mode:" + self.name)
  File "c:\users\schol\appdata\local\programs\python\python36\lib\site-packages\mpf\core\device.py", line 103, in validate_and_parse_config
    self.config_section, config, self.name, "device", prefix=debug_prefix)
  File "c:\users\schol\appdata\local\programs\python\python36\lib\site-packages\mpf\core\config_validator.py", line 281, in validate_config
    validation_failure_info=(validation_failure_info, k))
  File "c:\users\schol\appdata\local\programs\python\python36\lib\site-packages\mpf\core\config_validator.py", line 328, in validate_config_item
    new_list.append(self.validate_item(i, validation, validation_failure_info))
  File "c:\users\schol\appdata\local\programs\python\python36\lib\site-packages\mpf\core\config_validator.py", line 757, in validate_item
    return self.validator_list[validator](item, validation_failure_info=validation_failure_info, param=param)
  File "c:\users\schol\appdata\local\programs\python\python36\lib\site-packages\mpf\core\config_validator.py", line 436, in _validate_type_subconfig
    return self.validate_config(attribute, item, section_name=str(validation_failure_info), base_spec=base_spec)
  File "c:\users\schol\appdata\local\programs\python\python36\lib\site-packages\mpf\core\config_validator.py", line 251, in validate_config
    validation_failure_info)
  File "c:\users\schol\appdata\local\programs\python\python36\lib\site-packages\mpf\core\config_validator.py", line 418, in check_for_invalid_sections
    'setting name.', 2, self.log.name)
mpf.exceptions.config_file_error.ConfigFileError: Config File Error in ConfigValidator: Your config contains a value for the setting "timer_control_events:(('mode:mode_timer:timers', 'mode_overtime'), 'control_events'):events", but this is not a valid setting name. Error Code: CFE-ConfigValidator-2 (https://docs.missionpinball.org/en/dev/logs/CFE-ConfigValidator-2.html)
2020-02-09 15:54:31,130 : INFO : root : MPF run loop ended.
